Workbook

Sheet Table Index
A1: Public expenditure on ECE: table index and finder | I1: About the data in this table
A3: Use the drop down arrows to choose (filter) what information you require, then click on the Worksheet link to go directly to the table
A4: Financial year | B4: Measurement | C4: Service type 13 | D4: Programme 14 | E4: NZ Deprivation Index 18 | F4: Funding band 19 | G4: Geographical breakdown | H4: Equity funding 5 | I4: Worksheet | J4: Table name
A5: 2002 - 2023 | B5: Government expenditure on ECE | I5: EXP1 | J5: Total government expenditure on early childhood education by Vote ($000, GST exclusive)
A6: 2002 - 2023 | B6: Government expenditure on ECE | I6: EXP2 | J6: Vote Education expenditure on early childhood by funding direction ($000, GST exclusive)
A7: 2002 - 2023 | B7: ECE expenditure per funded child hour | I7: EXP3 | J7: Government expenditure on early childhood education per funded child hour and per full-time equivalent (FTE) ($, GST exclusive)
A8: 2002 - 2023 | B8: ECE expenditure as a proportion of GDP | I8: EXP4 | J8: ECE expenditure on early childhood education as a proportion of GDP, Public expenditure on education and Total Core Crown expenses ($000, GST exclusive)
A9: 2002 - 2023 | B9: Entitlement funding, Equity funding and Targeted Funding for Disadvantage | C9: Yes | D9: Yes | I9: EXP5 | J9: Entitlement funding and equity funding and targeted funding for disadvantage by service type and programme ($000, GST exclusive)
A10: 2002 - 2023 | B10: Entitlement funding, Equity funding and Targeted Funding for Disadvantage | D10: Yes | G10: Regional Council | I10: EXP6 | J10: Entitlement funding, equity funding and targeted funding for disadvantage by Regional Council and programme ($000, GST exclusive)
A11: 2002 - 2023 | B11: Entitlement funding, Equity funding and Targeted Funding for Disadvantage | D11: Yes | G11: Territorial Authority, Auckland Local Board | I11: EXP7 | J11: Entitlement funding, equity funding and targeted funding for disadvantage by Territorial Authority, Auckland Local Board and programme ($000, GST exclusive)
A12: 2002 - 2023 | B12: Entitlement funding, Equity funding and Targeted Funding for Disadvantage | D12: Yes | G12: Education Area | I12: EXP8 | J12: Entitlement funding, equity funding and targeted funding for disadvantage by Education Area and programme ($000, GST exclusive)
A13: 2002 - 2023 | B13: Entitlement funding, Equity funding and Targeted Funding for Disadvantage | D13: Yes | E13: Yes | I13: EXP9 | J13: Entitlement funding, equity funding and targeted funding for disadvantage by New Zealand Index of Deprivation and programme ($000, GST exclusive)
A14: 2002 - 2023 | B14: Funding per funded child hour | C14: Yes | D14: Yes | I14: EXP10 | J14: Entitlement funding, equity funding and targeted funding for disadvantage per funded child hour by service type and programme ($, GST exclusive)
A15: 2002 - 2023 | B15: Funding per funded child hour | D15: Yes | G15: Regional Council | I15: EXP11 | J15: Entitlement funding, equity funding and targeted funding for disadvantage per funded child hour by Regional Council and programme ($, GST exclusive)
A16: 2002 - 2023 | B16: Funding per funded child hour | D16: Yes | G16: Territorial Authority, Auckland Local Board | I16: EXP12 | J16: Entitlement funding, equity funding and targeted funding for disadvantage per funded child hour by Territorial Authority, Auckland Local Board and programme ($, GST exclusive)
A17: 2002 - 2023 | B17: Funding per funded child hour | D17: Yes | G17: Education Area | I17: EXP13 | J17: Entitlement funding, equity funding and targeted funding for disadvantage per funded child hour by Education Area and programme ($, GST exclusive)
A18: 2002 - 2023 | B18: Funding per funded child hour | D18: Yes | E18: Yes | I18: EXP14 | J18: Entitlement funding, equity funding and targeted funding for disadvantage per funded child hour by New Zealand Index of Deprivation and programme ($, GST exclusive)
A19: 2002 - 2023 | B19: Funded child hour | C19: Yes | D19: Yes | I19: EXP15 | J19: Funded child hours by service type and programme
A20: 2002 - 2023 | B20: Funded child hour | D20: Yes | G20: Regional Council | I20: EXP16 | J20: Funded child hours by Regional Council and programme
A21: 2002 - 2023 | B21: Funded child hour | D21: Yes | G21: Territorial Authority, Auckland Local Board | I21: EXP17 | J21: Funded child hours by Territorial Authority, Auckland Local Board and programme
A22: 2002 - 2023 | B22: Funded child hour | D22: Yes | G22: Education Area | I22: EXP18 | J22: Funded child hours funding by Education Area and programme
A23: 2002 - 2023 | B23: Funded child hour | D23: Yes | E23: Yes | I23: EXP19 | J23: Funded child hours by New Zealand Index of Deprivation and programme
A24: 2002 - 2023 | B24: Equity funding component A, B, C and D | C24: Yes | E24: Yes | I24: EXP20 | J24: Equity funding by New Zealand Index of Deprivation, service type and funding component ($, GST exclusive)
A25: 2006 - 2023 | B25: Entitlement funding | D25: Yes | F25: Yes | I25: EXP21 | J25: Entitlement funding by funding band ($000, GST exclusive)
A26: 2005 - 2023 | B26: Subsidy rates | C26: Yes | D26: Yes | F26: Yes | I26: EXP22 | J26: Subsidy rates ($, GST inclusive)
A27: 2002 - 2023 | B27: Equity Funding rates | H27: Yes | I27: EXP23 | J27: Equity Funding rates ($, GST inclusive)

Sheet Table Notes
A1: About these statistics | G1: Table Index
A2: 1 | B2: ECE Expenditure | C2: ECE expenditure has been reported in more than one way in this worksheet: - Tabs EXP1 -4 report the published MOE Financial Annual Accounts data, which uses audited Ministry of Education financial data. - Tabs EXP5-16 use data from the Early Childhood Funding Claim Forms (RS7s) database. Notes on the tables: - Dollar amounts in these tables (except for Tables EXP22 and EXP23) are GST-exclusive. - In all tables, all years are July to June financial years. - All dollar figures are nominal dollars, except those in Table 1 EXP3, which have been adjusted using CPI to 2023 dollars. - Dollar amounts may not always add to totals due to calculation rounding.
A3: 2 | B3: Core Crown expenses | C3: Day-to-day spending of the Crown, departments, Offices of Parliament, the NZ Superannuation Fund and the Reserve Bank of New Zealand, as sourced from Treasury's Economic and Fiscal Updates.
A4: 3 | B4: Total Vote Education, Vote Education Review Office (ERO) and Vote Social Development (MSD) | C4: The total government expenditure on early childhood education through Ministry of Education, Ministry of Social Development and Education Review Office. "Votes" refer to groups of similar or related appropriations (e.g. Vote Education includes all education-related appropriations administered by the Ministry of Education). Vote education review office is excluded as from 2020/21 as ERO is no longer able to provide their figures regarding spending specifically on early childhood education. There are slight differences between the Vote Education expense in early childhood education and the Core Crown Education expenses in early childhood education due to differences in the composition of expenditure items that are included. For more information see:
C5: https://budget.govt.nz/budget/2024/by/vote/index.htm
A6: 4 | B6: Vote Education Early Childhood Education Appropriation | C6: The total expenditure on ECE as reported in the Ministry of Education's Annual Report.
A7: 5 | B7: Equity Funding | C7: Equity Funding is a targeted funding mechanism paid to eligible services in addition to the ECE entitlement funding. Its objectives are to reduce educational disparities between different groups in New Zealand communities, reduce barriers to participation faced by those groups that are under represented in ECE services and to support ECE services in raising their level of educational achievement. Eligibility for Components A and B of equity funding are based on the service's Equity Index (EQI), which measures the extent to which a service draws children from low socio-economic communities. Component C provides targeted funding to support those services that provide early childhood education in a language and culture other than English (including sign language) during more than half of the formal education and care programme while Component D recognises that isolated services will face higher costs when accessing goods and services and provides services with an isolation index of 1.65 or greater with additional funding (See note 20 for more information on isolation index). The Equity funding value shown includes targeted funding for disadvantage since January 2017 (which is the primary source of the $10m growth between 16/17 and 18/19).
A8: 6 | B8: Targeted Funding for Disadvantage | C8: Targeted Funding for Disadvantage (Targeted Funding) is a targeted funding mechanism for licensed early childhood education (ECE) services and ngā kōhanga reo (early learning services). Targeted Funding is paid to eligible early learning services in addition to the ECE Funding Subsidy, 20 Hours ECE and Equity Funding. The objective of Targeted Funding is to improve educational equity by improving the quality and affordability of early learning for children/tamariki from disadvantaged backgrounds. Targeted Funding must be spent on activities, staff or equipment that will benefit children/tamariki from disadvantaged background. Targeted Funding for Disadvantage was introduced in 2018.
A9: 7 | B9: 2020 Lockdown Data Collection | C9: Funded child hours collected during Alert Level 3 and 4 of the COVID-19 Alert System were based on the enrolments recorded at the beginning of the year. While no actual hours were being generated throughout this period, services continued to receive funding based on these enrolment hours.
A10: 8 | B10: In 2023 dollars | C10: The dollar values have been adjusted for inflation using the CPI 2023 June quarter, sourced from Statistics New Zealand.
A11: 9 | B11: Funded child hours (FCH) | C11: Funded child hours are the hours for which a service may claim funding and for this reason will exclude those hours where a child attends beyond 6 hours in a day, or 30 hours in a week. Funded child hours in these tables do not include hours from unlicensed services with the exception of unlicensed Kōhanga reo.
A12: 10 | B12: Full-time equivalent (FTE) | C12: Full-time equivalent is nominally defined as 1,000 funded child hours per year.
A13: 11 | B13: GDP | C13: GDP figures are nominal GDP sourced from Financial Statements of the Government of New Zealand.
A14: 12 | B14: Total public expenditure on education | C14: Total public expenditure on education includes ECE, primary and secondary schools and tertiary funding expenses, departmental expenses and other education expenses, as sourced from Treasury's Economic and Fiscal Updates.
A15: 13 | B15: Service type | C15: The type of ECE service; e.g. education & care service, kindergarten, home-based service, playcentre, Kōhanga reo, etc. For information on the different service types, see:
C16: https://www.education.govt.nz/parents-and-caregivers/early-learning/starting-early-learning/types-early-learning
A17: 14 | B17: Programme | C17: Describes the ECE subsidy funding that is being referred to (20 Hours ECE, 2 and over - non 20 Hours ECE, Under 2's and Equity funding).
A18: 15 | B18: Regional Council | C18: The regional council area the service is located in. Note, all current and past data involving geographic breakdowns are based on the latest boundaries.
A19: 16 | B19: Territorial Authority | C19: The territorial authority area the service is located in. Data for Auckland City incorporates the changes in 2010 to a single "super city". Because of its size, data for Auckland City also includes a breakdown by local board, sub-units of territorial authorities. Care should be taken when interpreting the geographic location of home-based services, as these have been assigned to the location of the co-ordinator, or local or national office. Note that territorial authorities do not always correspond to regional council borders. All current and past data involving geographic breakdowns are based on the latest boundaries.
A20: 17 | B20: Education area | C20: The education area that the ECE service is located in. These are twelve administrative areas created by the Ministry of Education.
A21: 18 | B21: NZDep2018 Index of Deprivation | C21: A measure of socio-economic deprivation produced by the Ministry of Health based on information from the 2018 Census. This index was used across the whole period, from 2000 onwards. The more deprived an area, the higher the NZ Deprivation Index. The NZDep decile used here relates to the NZDep decile of the census area unit the service is located in, rather than where the children live. Care should be taken when interpreting the geographic location of home-based services, as these have been assigned to the location of the co-ordinator, or local or national office. More information on the NZ Deprivation Index can be found in:
C22: https://www.otago.ac.nz/wellington/departments/publichealth/research/hirp/otago020194.html
A23: 19 | B23: Funding band | C23: Funding band is determined by the percentage of qualified teachers/parents or qualification criteria, and the level of the operating structure (all-day vs). The percentage figures in the funding band refer to the number of ‘Registered Teacher Hours’ a service has as a proportion of the total number of regulated (ratio) staff hours. For more information see Chapter 3 of the ECE Funding Handbook Changes to the funding bands: In February 2011, the 80-99% and 100% funding bands were removed and replaced with a single 80%+ band. The 80-99% and 100% funding bands were re-introduced in January 2021
C24: https://www.education.govt.nz/education-professionals/early-learning/funding-and-financials/ece-funding-handbook/chapter-3-the-ece-funding-subsidy
A25: 20 | B25: Isolation Index | C25: The Isolation Index is a measure calculated and used by the Ministry of Education to rate the 'relative isolation' of each service. This is determined by measuring a service’s distance to the nearest towns/cities with population sizes of 5,000, 20,000, and 100,000.
A26: 21 | B26: ECE Entitlement Funding | C26: The sum of 20 Hours ECE, 2 and over - non 20 Hours ECE, Under 2's using Ministry of Education financial accounts data.
A27: 22 | B27: Blank values | C27: Blank values are shown in cells where there is no applicable data.
A28: 23 | B28: Attestation level | C28: The level of pay parity for Education and Care services. The pay parity opt-in scheme is a funding scheme for education and care services, including hospital-based services. Services that opt in can access higher funding rates for paying their certificated teachers at or above certain minimum salary steps. There are four salary scales which are Base, Parity, Extended Parity, and Full Parity. More information can be found below:
C29: https://www.education.govt.nz/education-professionals/early-learning/funding-and-financials/pay-parity-opt-scheme-education-and-care-services

Sheet EXP1
A1: ='Table Index'!J5 -> Total government expenditure on early childhood education by Vote ($000, GST exclusive) | E1: About the data in this table | H1: Table Index
A3: Year | B3: Core Crown Education expenses in Early Childhood Education 2 | C3: Vote Education Early Childhood Education Appropriation 4 | D3: Vote Education Review Office (ERO) | E3: Vote Social Development (MSD) | F3: Vote Education, Vote Education Review Office (ERO) and Vote Social Development (MSD) 3
A4: 2001/02 | B4: 343000 | C4: 306753 | D4: 3049 | E4: 52688 | F4: 362490
A5: 2002/03 | B5: 373000 | C5: 341744 | D5: 3557 | E5: 53096 | F5: 398397
A6: 2003/04 | B6: 393000 | C6: 362957 | D6: 5828 | E6: 55383 | F6: 424168
A7: 2004/05 | B7: 444000 | C7: 414954 | D7: 6646 | E7: 74412 | F7: 496012
A8: 2005/06 | B8: 555000 | C8: 518795 | D8: 8320 | E8: 100501 | F8: 627616
A9: 2006/07 | B9: 617000 | C9: 584321 | D9: 8287 | E9: 125564 | F9: 718172
A10: 2007/08 | B10: 860000 | C10: 828521 | D10: 8672 | E10: 130684 | F10: 967877
A11: 2008/09 | B11: 1030000 | C11: 1011387 | D11: 9463 | E11: 134255 | F11: 1155105
A12: 2009/10 | B12: 1184000 | C12: 1166112 | D12: 9193 | E12: 149995 | F12: 1325300
A13: 2010/11 | B13: 1340000 | C13: 1325710 | D13: 9708 | E13: 156847 | F13: 1492265
A14: 2011/12 | B14: 1355000 | C14: 1325170 | D14: 9820 | E14: 154426 | F14: 1489416
A15: 2012/13 | B15: 1436000 | C15: 1410309 | D15: 9610 | E15: 148087 | F15: 1568006
... A22: 2019/20 | B22: 2007000 | C22: 1990222.8 | D22: 11905 | E22: 107434 | F22: 2109561.8
A23: 2020/21 | B23: 2132000 | C23: 2119894.7 | E23: 111312 | F23: 2231206.7
A24: 2021/22 | B24: 2247000 | C24: 2238026 | E24: 102889 | F24: 2340915
A25: 2022/23 | B25: 2355000 | C25: 2342383.3 | E25: 108366 | F25: 2450749.3

Sheet EXP2
A1: ='Table Index'!J6 -> Vote Education expenditure on early childhood by funding direction ($000, GST exclusive) | F1: About the data in this table | I1: Table Index
A3: Year | B3: Entitlement funding for 20 Hours ECE | C3: Entitlement funding for 2 and over non-20 Hours ECE | D3: Entitlement funding for Under 2's | E3: Equity funding 5 | F3: Other | G3: Vote Education Early Childhood Education Appropriation 4
A4: 2001/02 | B4: 0 | C4: 216714 | D4: 85039 | E4: 1778 | F4: 3222 | G4: 306753
A5: 2002/03 | B5: 0 | C5: 235947 | D5: 94418 | E5: 8648 | F5: 2731 | G5: 341744
A6: 2003/04 | B6: 0 | C6: 249620 | D6: 101124 | E6: 9528 | F6: 2685 | G6: 362957
A7: 2004/05 | B7: 0 | C7: 289405 | D7: 111977 | E7: 9609 | F7: 3963 | G7: 414954
A8: 2005/06 | B8: 0 | C8: 365533 | D8: 139149 | E8: 9653 | F8: 4460 | G8: 518795
A9: 2006/07 | B9: 0 | C9: 392975 | D9: 161994 | E9: 9911 | F9: 19441 | G9: 584321
A10: 2007/08 | B10: 366497 | C10: 239877 | D10: 188768 | E10: 10127 | F10: 23252 | G10: 828521
A11: 2008/09 | B11: 523554 | C11: 246375 | D11: 206360 | E11: 10955 | F11: 24143 | G11: 1011387
A12: 2009/10 | B12: 624171 | C12: 270024 | D12: 234189 | E12: 11910 | F12: 25818 | G12: 1166112
A13: 2010/11 | B13: 752650 | C13: 277212 | D13: 257965 | E13: 12302 | F13: 25581 | G13: 1325710
A14: 2011/12 | B14: 762464 | C14: 274593 | D14: 254934 | E14: 14926 | F14: 18253 | G14: 1325170
A15: 2012/13 | B15: 805568 | C15: 288337 | D15: 264642 | E15: 37387 | F15: 14375 | G15: 1410309
... A25: 2022/23 | B25: 1190820.9 | C25: 538379.97 | D25: 504784.24 | E25: 68681.405 | F25: 39716.75 | G25: 2342383.3

Sheet EXP3
A1: ='Table Index'!J7 -> Government expenditure on early childhood education per funded child hour and per full-time equivalent (FTE) ($, GST exclusive) | H1: About the data in this table | K1: Table Index
A3: In 2023 dollars 8
A4: Year | B4: Funded child hours (FCHs) 9 | C4: Full-time equivalents 9 (1 FTE = 1,000 FCHs) | D4: ECE entitlement funding (000) 21 | E4: ECE entitlement funding per FCH | F4: ECE entitlement funding per FTE | G4: Vote Education Early Childhood Education Appropriation 4 (000) | H4: Vote Education ECE funding per FCH | I4: Vote Education ECE funding per FTE | J4: Total government ECE expenditure (000) 3 | K4: Total government ECE expenditure per FCH | L4: Total government ECE expenditure per FTE
A5: 2001/02 | B5: 94494000 | C5: 94493.567 | D5: 505915 | E5: 5.35 | F5: 5354 | G5: 514298 | H5: 5.44 | I5: 5443 | J5: 607746 | K5: 6.43 | L5: 6432
A6: 2002/03 | B6: 103393000 | C6: 103393.22 | D6: 545814 | E6: 5.28 | F6: 5279 | G6: 564614 | H6: 5.46 | I6: 5461 | J6: 658213 | K6: 6.37 | L6: 6366
A7: 2003/04 | B7: 107967000 | C7: 107966.97 | D7: 566079 | E7: 5.24 | F7: 5243 | G7: 585790 | H7: 5.43 | I7: 5426 | J7: 684581 | K7: 6.34 | L7: 6341
A8: 2004/05 | B8: 110925000 | C8: 110925.23 | D8: 629873 | E8: 5.68 | F8: 5678 | G8: 651171 | H8: 5.87 | I8: 5870 | J8: 778372 | K8: 7.02 | L8: 7017
A9: 2005/06 | B9: 114888000 | C9: 114888.29 | D9: 761669 | E9: 6.63 | F9: 6630 | G9: 782969 | H9: 6.82 | I9: 6815 | J9: 947202 | K9: 8.24 | L9: 8245
A10: 2006/07 | B10: 118089000 | C10: 118089.28 | D10: 821140 | E10: 6.95 | F10: 6954 | G10: 864569 | H10: 7.32 | I10: 7321 | J10: 1062617 | K10: 9 | L10: 8998
A11: 2007/08 | B11: 129519000 | C11: 129518.87 | D11: 1131040 | E11: 8.73 | F11: 8733 | G11: 1178519 | H11: 9.1 | I11: 9099 | J11: 1376744 | K11: 10.63 | L11: 10630
A12: 2008/09 | B12: 138458000 | C12: 138458.38 | D12: 1363017 | E12: 9.84 | F12: 9844 | G12: 1412018 | H12: 10.2 | I12: 10198 | J12: 1612665 | K12: 11.65 | L12: 11647
A13: 2009/10 | B13: 147537000 | C13: 147537.41 | D13: 1549558 | E13: 10.5 | F13: 10503 | G13: 1601368 | H13: 10.85 | I13: 10854 | J13: 1819973 | K13: 12.34 | L13: 12336
A14: 2010/11 | B14: 157014000 | C14: 157013.66 | D14: 1679858 | E14: 10.7 | F14: 10699 | G14: 1729274 | H14: 11.01 | I14: 11014 | J14: 1946530 | K14: 12.4 | L14: 12397
A15: 2011/12 | B15: 162339000 | C15: 162339.28 | D15: 1669418 | E15: 10.28 | F15: 10284 | G15: 1712290 | H15: 10.55 | I15: 10548 | J15: 1924517 | K15: 11.85 | L15: 11855
A16: 2012/13 | B16: 169675000 | C16: 169675.41 | D16: 1743476 | E16: 10.28 | F16: 10275 | G16: 1809904 | H16: 10.67 | I16: 10667 | J16: 2012282 | K16: 11.86 | L16: 11860
... A26: 2022/23 | B26: 223603000 | C26: 223603.16 | D26: 2233985 | E26: 9.99 | F26: 9991 | G26: 2342383 | H26: 10.48 | I26: 10476 | J26: 2450749 | K26: 10.96 | L26: 10960
A28: In nominal dollars
A29: Year | B29: Funded child hours (FCHs) 9 | C29: Full-time equivalents 9 (1 FTE = 1,000 FCHs) | D29: ECE entitlement funding (000) 21 | E29: ECE entitlement funding per FCH | F29: ECE entitlement funding per FTE | G29: Vote Education Early Childhood Education Appropriation 4 (000) | H29: Vote Education ECE funding per FCH | I29: Vote Education ECE funding per FTE | J29: Total government ECE expenditure (000) 3 | K29: Total government ECE expenditure per FCH | L29: Total government ECE expenditure per FTE
A30: 2001/02 | B30: 94494000 | C30: 94493.567 | D30: 301753 | E30: 3.1933708 | F30: 3193 | G30: 306753 | H30: 3.2462845 | I30: 3246 | J30: 362490 | K30: 3.8361342 | L30: 3836
A31: 2002/03 | B31: 103393000 | C31: 103393.22 | D31: 330365 | E31: 3.1952289 | F31: 3195 | G31: 341744 | H31: 3.3052845 | I31: 3305 | J31: 398397 | K31: 3.8532218 | L31: 3853
A32: 2003/04 | B32: 107967000 | C32: 107966.97 | D32: 350744 | E32: 3.2486232 | F32: 3249 | G32: 362957 | H32: 3.3617411 | I32: 3362 | J32: 424168 | K32: 3.928683 | L32: 3929
A33: 2004/05 | B33: 110925000 | C33: 110925.23 | D33: 401382 | E33: 3.6184914 | F33: 3618 | G33: 414954 | H33: 3.740844 | I33: 3741 | J33: 496012 | K33: 4.4715885 | L33: 4472
A34: 2005/06 | B34: 114888000 | C34: 114888.29 | D34: 504682 | E34: 4.3928062 | F34: 4393 | G34: 518795 | H34: 4.5156473 | I34: 4516 | J34: 627616 | K34: 5.4628369 | L34: 5463
A35: 2006/07 | B35: 118089000 | C35: 118089.28 | D35: 554969 | E35: 4.6995712 | F35: 4700 | G35: 584321 | H35: 4.9481289 | I35: 4948 | J35: 718172 | K35: 6.0816018 | L35: 6082
A36: 2007/08 | B36: 129519000 | C36: 129518.87 | D36: 795142 | E36: 6.139198 | F36: 6139 | G36: 828521 | H36: 6.3969133 | I36: 6397 | J36: 967877 | K36: 7.4728646 | L36: 7473
A37: 2008/09 | B37: 138458000 | C37: 138458.38 | D37: 976289 | E37: 7.0511368 | F37: 7051 | G37: 1011387 | H37: 7.3046281 | I37: 7305 | J37: 1155105 | K37: 8.3426151 | L37: 8343
A38: 2009/10 | B38: 147537000 | C38: 147537.41 | D38: 1128384 | E38: 7.6481212 | F38: 7648 | G38: 1166112 | H38: 7.9038394 | I38: 7904 | J38: 1325300 | K38: 8.9828065 | L38: 8983
A39: 2010/11 | B39: 157014000 | C39: 157013.66 | D39: 1287827 | E39: 8.2020061 | F39: 8202 | G39: 1325710 | H39: 8.4432781 | I39: 8443 | J39: 1492265 | K39: 9.5040457 | L39: 9504
A40: 2011/12 | B40: 162339000 | C40: 162339.28 | D40: 1291991 | E40: 7.9585853 | F40: 7959 | G40: 1325170 | H40: 8.1629659 | I40: 8163 | J40: 1489416 | K40: 9.1747112 | L40: 9175
A41: 2012/13 | B41: 169675000 | C41: 169675.41 | D41: 1358547 | E41: 8.0067408 | F41: 8007 | G41: 1410309 | H41: 8.3118057 | I41: 8312 | J41: 1568006 | K41: 9.2412097 | L41: 9241
... A51: 2022/23 | B51: 223603000 | C51: 223603.16 | D51: 2233985.2 | E51: 9.9908481 | F51: 9991 | G51: 2342383.3 | H51: 10.475627 | I51: 10476 | J51: 2450749.3 | K51: 10.960263 | L51: 10960

Sheet EXP4
A1: ='Table Index'!J8 -> ECE expenditure on early childhood education as a proportion of GDP, Public expenditure on education and Total Core Crown expenses ($000, GST exclusive) | H1: About the data in this table | K1: Table Index
A3: Year | B3: GDP 11 | C3: Vote Education ECE funding as a proportion of GDP | D3: Total government expenditure on ECE as a proportion of GDP | E3: Total public expenditure on education 12 | F3: Vote Education ECE funding as a proportion of total public expenditure on education | G3: Total government expenditure on ECE as a proportion of total public expenditure on education | H3: Total Core Crown Expenses 2 | I3: Vote Education ECE funding as a proportion of total Core Crown Expenses | J3: Total government expenditure on ECE as a proportion of total Core Crown Expenses
A4: 2001/02 | B4: 127511000 | C4: 0.0024056983 | D4: 0.0028428136 | E4: 6473000 | F4: 0.047389618 | G4: 0.056000309 | H4: 37970000 | I4: 0.0080788254 | J4: 0.0095467474
A5: 2002/03 | B5: 135673000 | C5: 0.00251888 | D5: 0.0029364501 | E5: 7016000 | F5: 0.048709236 | G5: 0.056784065 | H5: 41749000 | I5: 0.0081856811 | J5: 0.0095426717
A6: 2003/04 | B6: 146387000 | C6: 0.0024794346 | D6: 0.0028975797 | E6: 7585000 | F6: 0.047851945 | G6: 0.055921951 | H6: 41608000 | I6: 0.0087232503 | J6: 0.010194386
A7: 2004/05 | B7: 157101000 | C7: 0.0026413199 | D7: 0.003157281 | E7: 7930000 | F7: 0.052327112 | G7: 0.062548802 | H7: 44660000 | I7: 0.0092914017 | J7: 0.011106404
A8: 2005/06 | B8: 165027000 | C8: 0.0031436977 | D8: 0.003803111 | E8: 9914000 | F8: 0.052329534 | G8: 0.063306032 | H8: 49084000 | I8: 0.010569534 | J8: 0.01278657
A9: 2006/07 | B9: 175047000 | C9: 0.0033380806 | D9: 0.0041027381 | E9: 9269000 | F9: 0.06304035 | G9: 0.077481066 | H9: 53764000 | I9: 0.010868258 | J9: 0.01335786
A10: 2007/08 | B10: 188147000 | C10: 0.0044035834 | D10: 0.0051442595 | E10: 9551000 | F10: 0.086747042 | G10: 0.10133777 | H10: 56753000 | I10: 0.014598717 | J10: 0.0170542
A11: 2008/09 | B11: 189554000 | C11: 0.0053356141 | D11: 0.0060938044 | E11: 11455000 | F11: 0.088292187 | G11: 0.1008385 | H11: 63711000 | I11: 0.015874606 | J11: 0.018130386
A12: 2009/10 | B12: 196734000 | C12: 0.0059273537 | D12: 0.0067365072 | E12: 11724000 | F12: 0.099463664 | G12: 0.11304162 | H12: 63554000 | I12: 0.018348365 | J12: 0.020853133
A13: 2010/11 | B13: 205876000 | C13: 0.0064393616 | D13: 0.0072483679 | E13: 11650000 | F13: 0.11379485 | G13: 0.12809142 | H13: 70099000 | I13: 0.018911967 | J13: 0.021287964
A14: 2011/12 | B14: 214977000 | C14: 0.0061642408 | D14: 0.0069282574 | E14: 11654000 | F14: 0.11370946 | G14: 0.12780299 | H14: 68939000 | I14: 0.019222356 | J14: 0.021604839
A15: 2012/13 | B15: 218838000 | C15: 0.0064445343 | D15: 0.007165145 | E15: 12504000 | F15: 0.11278863 | G15: 0.12540035 | H15: 69962000 | I15: 0.020158214 | J15: 0.022412252
... A25: 2022/23 | B25: 395896000 | C25: 0.0059166632 | D25: 0.0061903866 | E25: 18403000 | F25: 0.12728269 | G25: 0.13317118 | H25: 127574000 | I25: 0.018360977 | J25: 0.019210414

Sheet EXP5
A1: ='Table Index'!J9 -> Entitlement funding and equity funding and targeted funding for disadvantage by service type and programme ($000, GST exclusive) | M1: About the data in this table | P1: Table Index
A2: Note that for this table, Education & Care services includes both Casual Education & Care and Hospital-based services. Kōhanga reo includes unlicensed Kōhanga reo up to 2008.
A4: Click on arrow to select (filter) the information you need
A5: Service type 13 | B5: Programme 14 | C5: 2001/02 | D5: 2002/03 | E5: 2003/04 | F5: 2004/05 | G5: 2005/06 | H5: 2006/07 | I5: 2007/08 | J5: 2008/09 | K5: 2009/10 | L5: 2010/11 | M5: 2011/12 | N5: 2012/13 | O5: 2013/14 | P5: 2014/15 | Q5: 2015/16 | R5: 2016/17 | S5: 2017/18 | T5: 2018/19 | U5: 2019/20 | V5: 2020/21 | W5: 2021/22 | X5: 2022/23
A6: Education & Care | B6: 20 Hours ECE | C6: 0 | D6: 0 | E6: 0 | F6: 0 | G6: 0 | H6: 0 | I6: 222343.06 | J6: 342122.01 | K6: 417329.39 | L6: 471854.54 | M6: 508505.07 | N6: 550360.78 | O6: 601756.02 | P6: 647445.23 | Q6: 682799.74 | R6: 694187.8 | S6: 707888.05 | T6: 729497.47 | U6: 769860.59 | V6: 820559.74 | W6: 834522.28 | X6: 875048.6
A7: Education & Care | B7: Under 2's | C7: 57534.38 | D7: 60856.71 | E7: 68591.895 | F7: 79216.739 | G7: 102834.86 | H7: 119878.39 | I7: 144379.8 | J7: 163706.66 | K7: 182168.2 | L7: 187839.75 | M7: 191914.48 | N7: 201140.17 | O7: 219030.55 | P7: 229790.42 | Q7: 246861.62 | R7: 260956.86 | S7: 278573.75 | T7: 294461.51 | U7: 301498.69 | V7: 337604.39 | W7: 367034.44 | X7: 425089.92
A8: Education & Care | B8: 2 and over - non 20 Hours ECE | C8: 108092.62 | D8: 118903.16 | E8: 130228.02 | F8: 147006.33 | G8: 193303.63 | H8: 231756.26 | I8: 172599.72 | J8: 187362.07 | K8: 201943.9 | L8: 204971.11 | M8: 205910.79 | N8: 218237.26 | O8: 235372.9 | P8: 253997.02 | Q8: 270108.92 | R8: 291528 | S8: 307314.23 | T8: 326756.41 | U8: 342456.45 | V8: 355602.84 | W8: 380335.13 | X8: 412442.91
A9: Education & Care | B9: Equity | C9: 1118.0497 | D9: 2318.3732 | E9: 2395.9037 | F9: 2526.439 | G9: 2734.7008 | H9: 3023.743 | I9: 3250.3528 | J9: 3780.1861 | K9: 3910.5813 | L9: 4188.4669 | M9: 7794.3284 | N9: 13804.011 | O9: 21729.111 | P9: 24480.936 | Q9: 26895.82 | R9: 28790.269 | S9: 30292.558 | T9: 30901.279 | U9: 32363.996 | V9: 33131.183 | W9: 33804.414 | X9: 34286.359
A10: Education & Care | B10: Targeted Funding for Disadvantage | C10: 0 | D10: 0 | E10: 0 | F10: 0 | G10: 0 | H10: 0 | I10: 0 | J10: 0 | K10: 0 | L10: 0 | M10: 0 | N10: 0 | O10: 0 | P10: 0 | Q10: 0 | R10: 0 | S10: 2895.2497 | T10: 5697.801 | U10: 5826.9885 | V10: 6126.3149 | W10: 6125.1714 | X10: 6201.4536
A11: Education & Care | B11: Total | C11: 166745.05 | D11: 182078.24 | E11: 201215.82 | F11: 228749.51 | G11: 298873.19 | H11: 354658.4 | I11: 542572.94 | J11: 696970.92 | K11: 805352.08 | L11: 868853.87 | M11: 914124.68 | N11: 983542.22 | O11: 1077888.6 | P11: 1155713.6 | Q11: 1226666.1 | R11: 1275462.9 | S11: 1326963.8 | T11: 1387314.5 | U11: 1452006.7 | V11: 1553024.5 | W11: 1621821.4 | X11: 1753069.2
A12: Home-based | B12: 20 Hours ECE | C12: 0 | D12: 0 | E12: 0 | F12: 0 | G12: 0 | H12: 0 | I12: 19182.942 | J12: 26795.446 | K12: 31411.061 | L12: 34188.032 | M12: 36499.161 | N12: 37627.019 | O12: 38885.02 | P12: 39543.777 | Q12: 41205.398 | R12: 42089.094 | S12: 40401.127 | T12: 37343.841 | U12: 35313.174 | V12: 31543.444 | W12: 30072.62 | X12: 26831.52
A13: Home-based | B13: Under 2's | C13: 13625.756 | D13: 14401.603 | E13: 15705.489 | F13: 17102.098 | G13: 18364.58 | H13: 20160.513 | I13: 24500.882 | J13: 27201.165 | K13: 31083.618 | L13: 34770.669 | M13: 35097.57 | N13: 36396.035 | O13: 40238.995 | P13: 49139.83 | Q13: 56551.791 | R13: 53430.42 | S13: 54802.446 | T13: 51392.494 | U13: 44605.31 | V13: 39066.215 | W13: 38106.674 | X13: 34928.171
A14: Home-based | B14: 2 and over - non 20 Hours ECE | C14: 11334.13 | D14: 11851.419 | E14: 13041.235 | F14: 14443.85 | G14: 16089.074 | H14: 18231.912 | I14: 14874.655 | J14: 16413.532 | K14: 18287.19 | L14: 20431.6 | M14: 21831.193 | N14: 22754.551 | O14: 23695.991 | P14: 27011.843 | Q14: 31072.2 | R14: 32502.945 | S14: 33939.781 | T14: 33679.321 | U14: 31641.571 | V14: 27821.181 | W14: 25627.597 | X14: 23969.965
A15: Home-based | B15: Equity | C15: 68.75527 | D15: 112.49186 | E15: 108.55571 | F15: 89.888277 | G15: 83.809199 | H15: 80.335387 | I15: 124.14015 | J15: 176.70745 | K15: 170.35258 | L15: 168.54594 | M15: 644.48012 | N15: 1456.8393 | O15: 2833.8738 | P15: 3671.7006 | Q15: 4550.5193 | R15: 5501.2547 | S15: 6626.3609 | T15: 6635.2399 | U15: 6520.2773 | V15: 5338.2088 | W15: 4804.2376 | X15: 4218.6524
A16: Home-based | B16: Targeted Funding for Disadvantage | C16: 0 | D16: 0 | E16: 0 | F16: 0 | G16: 0 | H16: 0 | I16: 0 | J16: 0 | K16: 0 | L16: 0 | M16: 0 | N16: 0 | O16: 0 | P16: 0 | Q16: 0 | R16: 0 | S16: 533.83204 | T16: 1009.0491 | U16: 1006.6591 | V16: 940.17879 | W16: 864.36943 | X16: 707.78679
A17: Home-based | B17: Total | C17: 25028.641 | D17: 26365.513 | E17: 28855.279 | F17: 31635.836 | G17: 34537.463 | H17: 38472.761 | I17: 58682.619 | J17: 70586.85 | K17: 80952.221 | L17: 89558.847 | M17: 94072.404 | N17: 98234.445 | O17: 105653.88 | P17: 119367.15 | Q17: 133379.91 | R17: 133523.71 | S17: 136303.55 | T17: 130059.94 | U17: 119086.99 | V17: 104709.23 | W17: 99475.498 | X17: 90656.095
... A41: Total | B41: Total | C41: 302864.04 | D41: 344391.96 | E41: 373238.91 | F41: 411706.92 | G41: 496476.84 | H41: 564286.95 | I41: 817900.71 | J41: 1026788.4 | K41: 1169325 | L41: 1255904 | M41: 1305814.3 | N41: 1388788.3 | O41: 1508694.3 | P41: 1607689.9 | Q41: 1698932.7 | R41: 1753786.4 | S41: 1810524.3 | T41: 1869377.8 | U41: 1962027.7 | V41: 2096777.7 | W41: 2172070.9 | X41: 2316512.2

Sheet EXP6
A1: ='Table Index'!J10 -> Entitlement funding, equity funding and targeted funding for disadvantage by Regional Council and programme ($000, GST exclusive) | M1: About the data in this table | P1: Table Index
A3: Click on arrow to select (filter) the information you need
A4: Regional Council 15 | B4: Programme 14 | C4: 2001/02 | D4: 2002/03 | E4: 2003/04 | F4: 2004/05 | G4: 2005/06 | H4: 2006/07 | I4: 2007/08 | J4: 2008/09 | K4: 2009/10 | L4: 2010/11 | M4: 2011/12 | N4: 2012/13 | O4: 2013/14 | P4: 2014/15 | Q4: 2015/16 | R4: 2016/17 | S4: 2017/18 | T4: 2018/19 | U4: 2019/20 | V4: 2020/21 | W4: 2021/22 | X4: 2022/23
A5: Area outside regions | B5: 20 Hours ECE | C5: 0 | D5: 0 | E5: 0 | F5: 0 | G5: 0 | H5: 0 | I5: 6.41376 | J5: 52.176071 | K5: 49.490667 | L5: 42.750278 | M5: 54.611122 | N5: 37.866174 | O5: 34.909983 | P5: 59.211478 | Q5: 66.840261 | R5: 49.756696 | S5: 32.189565 | T5: 60.556991 | U5: 59.954765 | V5: 72.17713 | W5: 27.198322 | X5: 99.027757
A6: Area outside regions | B6: Under 2's | C6: 21.66112 | D6: 33.13856 | E6: 34.13296 | F6: 28.5152 | G6: 33.84736 | H6: 30.870187 | I6: 34.207253 | J6: 50.157707 | K6: 31.761739 | L6: 36.696261 | M6: 24.102783 | N6: 25.73687 | O6: 39.442852 | P6: 32.008487 | Q6: 28.180383 | R6: 25.366957 | S6: 24.997983 | T6: 33.442748 | U6: 60.192678 | V6: 78.0048 | W6: 19.983026 | X6: 17.444191
A7: Area outside regions | B7: 2 and over - non 20 Hours ECE | C7: 26.51488 | D7: 45.94432 | E7: 46.06848 | F7: 47.437867 | G7: 43.76288 | H7: 35.461333 | I7: 34.2328 | J7: 33.131609 | K7: 29.443555 | L7: 28.274157 | M7: 28.3138 | N7: 34.7168 | O7: 46.877217 | P7: 50.237635 | Q7: 44.048661 | R7: 46.284104 | S7: 42.963757 | T7: 41.993096 | U7: 57.631496 | V7: 85.034035 | W7: 160.69296 | X7: 115.26205
A8: Area outside regions | B8: Equity | C8: 2.1173333 | D8: 4.2346667 | E8: 4.2346667 | F8: 4.2346667 | G8: 4.2346667 | H8: 4.2346667 | I8: 4.2346667 | J8: 4.8714667 | K8: 4.8714589 | L8: 4.8713739 | M8: 4.8713739 | N8: 6.1597565 | O8: 7.3174957 | P8: 7.3174957 | Q8: 7.3174957 | R8: 7.3174957 | S8: 7.3174957 | T8: 7.3174957 | U8: 7.3833391 | V8: 7.5087652 | W8: 7.6137391 | X8: 7.7644174
A9: Area outside regions | B9: Targeted Funding for Disadvantage | C9: 0 | D9: 0 | E9: 0 | F9: 0 | G9: 0 | H9: 0 | I9: 0 | J9: 0 | K9: 0 | L9: 0 | M9: 0 | N9: 0 | O9: 0 | P9: 0 | Q9: 0 | R9: 0 | S9: 0 | T9: 0.44922609 | U9: 0.89845217 | V9: 0 | W9: 0.59543478 | X9: 2.0767826
A10: Area outside regions | B10: Total | C10: 50.293333 | D10: 83.317547 | E10: 84.436107 | F10: 80.187733 | G10: 81.844907 | H10: 70.566187 | I10: 79.08848 | J10: 140.33685 | K10: 115.56742 | L10: 112.59207 | M10: 111.89908 | N10: 104.4796 | O10: 128.54755 | P10: 148.7751 | Q10: 146.3868 | R10: 128.72525 | S10: 107.4688 | T10: 143.75956 | U10: 186.06073 | V10: 242.72473 | W10: 216.08348 | X10: 241.5752
A11: Auckland Region | B11: 20 Hours ECE | C11: 0 | D11: 0 | E11: 0 | F11: 0 | G11: 0 | H11: 0 | I11: 113998.8 | J11: 168692.43 | K11: 203363.98 | L11: 230164.97 | M11: 249196.73 | N11: 268516.8 | O11: 295831.36 | P11: 322235.06 | Q11: 339620.36 | R11: 342882.25 | S11: 348249.08 | T11: 353470.41 | U11: 368092.45 | V11: 387788.44 | W11: 389868 | X11: 403422.35
A12: Auckland Region | B12: Under 2's | C12: 26930.94 | D12: 28963.37 | E12: 32209.971 | F12: 35594.274 | G12: 43780.998 | H12: 50947.456 | I12: 61963.563 | J12: 68666.265 | K12: 75421.182 | L12: 78638.063 | M12: 80791.473 | N12: 86256.612 | O12: 96457.739 | P12: 110196.31 | Q12: 122756.65 | R12: 123540.69 | S12: 131388.82 | T12: 136558.28 | U12: 136255.47 | V12: 149301.91 | W12: 160653.23 | X12: 182345.52
A13: Auckland Region | B13: 2 and over - non 20 Hours ECE | C13: 66444.366 | D13: 73664.87 | E13: 79981.033 | F13: 88839.166 | G13: 107012.15 | H13: 123711.74 | I13: 79024.212 | J13: 84402.684 | K13: 90063.195 | L13: 91898.253 | M13: 93352.37 | N13: 98646.412 | O13: 107040.79 | P13: 119874.18 | Q13: 132926.97 | R13: 145005.9 | S13: 151324.47 | T13: 159929.02 | U13: 166317.12 | V13: 170655.84 | W13: 182163.11 | X13: 197494.89
A14: Auckland Region | B14: Equity | C14: 1096.0746 | D14: 2252.6137 | E14: 2272.4918 | F14: 2332.9614 | G14: 2394.6569 | H14: 2474.2246 | I14: 2586.1499 | J14: 3041.4109 | K14: 3083.4176 | L14: 3290.2907 | M14: 5020.5835 | N14: 8989.6508 | O14: 14205.827 | P14: 16218.631 | Q14: 18287.272 | R14: 19988.948 | S14: 21843.08 | T14: 22332.623 | U14: 22926.266 | V14: 22507.615 | W14: 23036.16 | X14: 23173.118
A15: Auckland Region | B15: Targeted Funding for Disadvantage | C15: 0 | D15: 0 | E15: 0 | F15: 0 | G15: 0 | H15: 0 | I15: 0 | J15: 0 | K15: 0 | L15: 0 | M15: 0 | N15: 0 | O15: 0 | P15: 0 | Q15: 0 | R15: 0 | S15: 1432.6327 | T15: 2764.6728 | U15: 2748.8357 | V15: 2808.5971 | W15: 2888.8915 | X15: 3012.2132
A16: Auckland Region | B16: Total | C16: 94471.381 | D16: 104880.85 | E16: 114463.5 | F16: 126766.4 | G16: 153187.81 | H16: 177133.42 | I16: 257572.73 | J16: 324802.79 | K16: 371931.78 | L16: 403991.58 | M16: 428361.16 | N16: 462409.47 | O16: 513535.71 | P16: 568524.18 | Q16: 613591.26 | R16: 631417.78 | S16: 654238.08 | T16: 675055.01 | U16: 696340.14 | V16: 733062.4 | W16: 758609.4 | X16: 809448.08
... A118: Total | B118: Total | C118: 302864.04 | D118: 344391.96 | E118: 373238.91 | F118: 411706.92 | G118: 496476.84 | H118: 564286.95 | I118: 817900.71 | J118: 1026788.4 | K118: 1169325 | L118: 1255904 | M118: 1305814.3 | N118: 1388788.3 | O118: 1508694.3 | P118: 1607689.9 | Q118: 1698932.7 | R118: 1753786.4 | S118: 1810524.3 | T118: 1869377.8 | U118: 1962027.7 | V118: 2096777.7 | W118: 2172070.9 | X118: 2316512.2

Sheet EXP7
A1: ='Table Index'!J11 -> Entitlement funding, equity funding and targeted funding for disadvantage by Territorial Authority, Auckland Local Board and programme ($000, GST exclusive) | M1: About the data in this table | P1: Table Index
A3: Click on arrow to select (filter) the information you need
A4: Territorial Authority with Auckland Local Boards 16 | B4: Programme 14 | C4: 2001/02 | D4: 2002/03 | E4: 2003/04 | F4: 2004/05 | G4: 2005/06 | H4: 2006/07 | I4: 2007/08 | J4: 2008/09 | K4: 2009/10 | L4: 2010/11 | M4: 2011/12 | N4: 2012/13 | O4: 2013/14 | P4: 2014/15 | Q4: 2015/16 | R4: 2016/17 | S4: 2017/18 | T4: 2018/19 | U4: 2019/20 | V4: 2020/21 | W4: 2021/22 | X4: 2022/23
A5: Ashburton District | B5: 20 Hours ECE | C5: 0 | D5: 0 | E5: 0 | F5: 0 | G5: 0 | H5: 0 | I5: 2296.3973 | J5: 3257.8284 | K5: 4216.4768 | L5: 4666.3239 | M5: 5595.6002 | N5: 5735.0774 | O5: 6156.7454 | P5: 6533.5046 | Q5: 6634.9328 | R5: 6598.0277 | S5: 6481.5036 | T5: 6594.0561 | U5: 7254.6708 | V5: 7498.9216 | W5: 7580.4521 | X5: 7692.5822
A6: Ashburton District | B6: Under 2's | C6: 307.78575 | D6: 328.49294 | E6: 319.53815 | F6: 339.17457 | G6: 450.06112 | H6: 590.9631 | I6: 647.44047 | J6: 949.97955 | K6: 1246.8987 | L6: 1332.6977 | M6: 1593.4135 | N6: 1529.3208 | O6: 1579.383 | P6: 1449.0101 | Q6: 1543.1482 | R6: 1780.1966 | S6: 1923.645 | T6: 1864.2111 | U6: 1949.8956 | V6: 2103.8207 | W6: 2410.9495 | X6: 2426.7238
A7: Ashburton District | B7: 2 and over - non 20 Hours ECE | C7: 1098.3943 | D7: 1159.9427 | E7: 1295.7525 | F7: 1428.3692 | G7: 1685.7782 | H7: 1855.4885 | I7: 657.95379 | J7: 1004.5344 | K7: 1351.9787 | L7: 1281.4912 | M7: 1399.1195 | N7: 1610.9926 | O7: 1650.8738 | P7: 1660.1883 | Q7: 1631.8798 | R7: 1706.7688 | S7: 1864.2585 | T7: 2066.1758 | U7: 2076.6151 | V7: 2156.4164 | W7: 2268.0591 | X7: 2552.671
A8: Ashburton District | B8: Equity | C8: 0 | D8: 0 | E8: 0 | F8: 0 | G8: 0 | H8: 0 | I8: 2.2096 | J8: 5.8510222 | K8: 6.0166564 | L8: 6.2254 | M8: 8.3900087 | N8: 26.090122 | O8: 50.188 | P8: 56.849157 | Q8: 61.25307 | R8: 59.875296 | S8: 52.396739 | T8: 51.214009 | U8: 54.524565 | V8: 54.88007 | W8: 67.627252 | X8: 63.616617
A9: Ashburton District | B9: Targeted Funding for Disadvantage | C9: 0 | D9: 0 | E9: 0 | F9: 0 | G9: 0 | H9: 0 | I9: 0 | J9: 0 | K9: 0 | L9: 0 | M9: 0 | N9: 0 | O9: 0 | P9: 0 | Q9: 0 | R9: 0 | S9: 13.651148 | T9: 23.796522 | U9: 19.767757 | V9: 24.11007 | W9: 20.349626 | X9: 18.125189
A10: Ashburton District | B10: Total | C10: 1406.18 | D10: 1488.4356 | E10: 1615.2906 | F10: 1767.5438 | G10: 2135.8393 | H10: 2446.4516 | I10: 3604.0012 | J10: 5218.1934 | K10: 6821.3708 | L10: 7286.7382 | M10: 8596.5232 | N10: 8901.4809 | O10: 9437.1902 | P10: 9699.5521 | Q10: 9871.2139 | R10: 10144.868 | S10: 10335.455 | T10: 10599.454 | U10: 11355.474 | V10: 11838.149 | W10: 12347.438 | X10: 12753.719
A11: Auckland: Albert-Eden | B11: 20 Hours ECE | C11: 0 | D11: 0 | E11: 0 | F11: 0 | G11: 0 | H11: 0 | I11: 7228.6484 | J11: 11598.916 | K11: 13429.694 | L11: 14450.494 | M11: 15108.889 | N11: 16320.092 | O11: 18099.242 | P11: 19746.589 | Q11: 20711.114 | R11: 20874.82 | S11: 20339.997 | T11: 20261.224 | U11: 20728.45 | V11: 21805.467 | W11: 20839.811 | X11: 20890.673
A12: Auckland: Albert-Eden | B12: Under 2's | C12: 2057.2629 | D12: 2101.5888 | E12: 2446.935 | F12: 2675.2059 | G12: 3399.5106 | H12: 3585.3077 | I12: 4463.7194 | J12: 5043.0848 | K12: 5544.7199 | L12: 5646.1843 | M12: 5648.8518 | N12: 6168.5022 | O12: 6662.4175 | P12: 9633.7947 | Q12: 10924.607 | R12: 9647.2893 | S12: 9673.0051 | T12: 9500.2322 | U12: 9516.9439 | V12: 10494.575 | W12: 10442.44 | X12: 11328.799
A13: Auckland: Albert-Eden | B13: 2 and over - non 20 Hours ECE | C13: 5127.5941 | D13: 5551.7282 | E13: 6007.5737 | F13: 6546.7572 | G13: 7952.923 | H13: 9193.2589 | I13: 6563.5696 | J13: 6950.4463 | K13: 6882.4832 | L13: 6806.4339 | M13: 6674.7113 | N13: 6740.3607 | O13: 7003.7975 | P13: 8030.4395 | Q13: 8638.5878 | R13: 9034.6593 | S13: 9043.8883 | T13: 9800.4551 | U13: 10314.04 | V13: 10653.291 | W13: 10573.897 | X13: 10977.985
A14: Auckland: Albert-Eden | B14: Equity | C14: 17.492348 | D14: 34.20395 | E14: 35.44926 | F14: 38.25338 | G14: 40.86544 | H14: 41.431973 | I14: 35.870667 | J14: 31.185467 | K14: 30.960136 | L14: 30.190113 | M14: 39.256089 | N14: 49.900812 | O14: 77.978991 | P14: 99.073609 | Q14: 126.69403 | R14: 135.78715 | S14: 140.59324 | T14: 139.48331 | U14: 144.78093 | V14: 153.1636 | W14: 142.73339 | X14: 159.21486
A15: Auckland: Albert-Eden | B15: Targeted Funding for Disadvantage | C15: 0 | D15: 0 | E15: 0 | F15: 0 | G15: 0 | H15: 0 | I15: 0 | J15: 0 | K15: 0 | L15: 0 | M15: 0 | N15: 0 | O15: 0 | P15: 0 | Q15: 0 | R15: 0 | S15: 13.098552 | T15: 23.916972 | U15: 21.267845 | V15: 25.561026 | W15: 35.359948 | X15: 50.328539
A16: Auckland: Albert-Eden | B16: Total | C16: 7202.3493 | D16: 7687.521 | E16: 8489.958 | F16: 9260.2165 | G16: 11393.299 | H16: 12819.999 | I16: 18291.808 | J16: 23623.633 | K16: 25887.857 | L16: 26933.303 | M16: 27471.708 | N16: 29278.856 | O16: 31843.436 | P16: 37509.897 | Q16: 40401.003 | R16: 39692.555 | S16: 39210.582 | T16: 39725.312 | U16: 40725.483 | V16: 43132.058 | W16: 42034.242 | X16: 43407
... A538: Total | B538: Total | C538: 302864.04 | D538: 344391.96 | E538: 373238.91 | F538: 411706.92 | G538: 496476.84 | H538: 564286.95 | I538: 817900.71 | J538: 1026788.4 | K538: 1169325 | L538: 1255904 | M538: 1305814.3 | N538: 1388788.3 | O538: 1508694.3 | P538: 1607689.9 | Q538: 1698932.7 | R538: 1753786.4 | S538: 1810524.3 | T538: 1869377.8 | U538: 1962027.7 | V538: 2096777.7 | W538: 2172070.9 | X538: 2316512.2

Sheet EXP8
A1: ='Table Index'!J12 -> Entitlement funding, equity funding and targeted funding for disadvantage by Education Area and programme ($000, GST exclusive) | M1: About the data in this table | P1: Table Index
A3: Click on arrow to select (filter) the information you need
A4: Education Area 17 | B4: Programme 14 | C4: 2001/02 | D4: 2002/03 | E4: 2003/04 | F4: 2004/05 | G4: 2005/06 | H4: 2006/07 | I4: 2007/08 | J4: 2008/09 | K4: 2009/10 | L4: 2010/11 | M4: 2011/12 | N4: 2012/13 | O4: 2013/14 | P4: 2014/15 | Q4: 2015/16 | R4: 2016/17 | S4: 2017/18 | T4: 2018/19 | U4: 2019/20 | V4: 2020/21 | W4: 2021/22 | X4: 2022/23
A5: Tai Tokerau | B5: 20 Hours ECE | C5: 0 | D5: 0 | E5: 0 | F5: 0 | G5: 0 | H5: 0 | I5: 12158.08 | J5: 19975.539 | K5: 22472.478 | L5: 23744.766 | M5: 25459.052 | N5: 26882.552 | O5: 29601.914 | P5: 31817.19 | Q5: 33646.945 | R5: 35112.508 | S5: 35298.304 | T5: 35787.297 | U5: 38157.615 | V5: 41818.909 | W5: 42404.646 | X5: 44980.595
A6: Tai Tokerau | B6: Under 2's | C6: 3098.4558 | D6: 3678.6106 | E6: 3732.136 | F6: 4015.8985 | G6: 4936.7206 | H6: 5795.6387 | I6: 6832.006 | J6: 7795.2452 | K6: 8180.3661 | L6: 8114.8495 | M6: 8560.0579 | N6: 8881.7464 | O6: 9682.9553 | P6: 10216.395 | Q6: 10825.129 | R6: 11973.261 | S6: 12678.265 | T6: 12376.747 | U6: 13074.321 | V6: 14791.591 | W6: 15781.172 | X6: 16893.74
A7: Tai Tokerau | B7: 2 and over - non 20 Hours ECE | C7: 7198.028 | D7: 8510.8417 | E7: 8915.5132 | F7: 9436.3789 | G7: 11234.881 | H7: 12677.402 | I7: 7856.1585 | J7: 8725.3828 | K7: 9427.5129 | L7: 9354.4181 | M7: 9032.6996 | N7: 9760.9301 | O7: 10359.38 | P7: 11610.018 | Q7: 12783.645 | R7: 13875.322 | S7: 14368.25 | T7: 15054.534 | U7: 16568.699 | V7: 17751.366 | W7: 19348.383 | X7: 20442.88
A8: Tai Tokerau | B8: Equity | C8: 420.69036 | D8: 845.44396 | E8: 816.44398 | F8: 769.34053 | G8: 798.00672 | H8: 767.16563 | I8: 750.67366 | J8: 888.95095 | K8: 883.73946 | L8: 930.85733 | M8: 1207.2758 | N8: 2003.5997 | O8: 2948.3643 | P8: 3168.8151 | Q8: 3351.5516 | R8: 3749.0302 | S8: 3978.5977 | T8: 4023.5771 | U8: 4180.2153 | V8: 4200.6642 | W8: 4174.1284 | X8: 4181.2546
A9: Tai Tokerau | B9: Targeted Funding for Disadvantage | C9: 0 | D9: 0 | E9: 0 | F9: 0 | G9: 0 | H9: 0 | I9: 0 | J9: 0 | K9: 0 | L9: 0 | M9: 0 | N9: 0 | O9: 0 | P9: 0 | Q9: 0 | R9: 0 | S9: 332.14417 | T9: 659.29702 | U9: 659.54064 | V9: 685.69166 | W9: 703.60782 | X9: 717.57158
A10: Tai Tokerau | B10: Total | C10: 10717.174 | D10: 13034.896 | E10: 13464.093 | F10: 14221.618 | G10: 16969.609 | H10: 19240.206 | I10: 27596.918 | J10: 37385.118 | K10: 40964.097 | L10: 42144.891 | M10: 44259.086 | N10: 47528.828 | O10: 52592.614 | P10: 56812.418 | Q10: 60607.271 | R10: 64710.121 | S10: 66655.56 | T10: 67901.451 | U10: 72640.391 | V10: 79248.222 | W10: 82411.938 | X10: 87216.04
A11: Tāmaki Herenga Manawa | B11: 20 Hours ECE | C11: 0 | D11: 0 | E11: 0 | F11: 0 | G11: 0 | H11: 0 | I11: 31486.271 | J11: 46468.989 | K11: 53257.773 | L11: 58452.289 | M11: 66890.124 | N11: 77263.49 | O11: 88665.798 | P11: 96565.025 | Q11: 101377.56 | R11: 103742.18 | S11: 105505.29 | T11: 107696.1 | U11: 111931.49 | V11: 118692.06 | W11: 117910.09 | X11: 121901.45
A12: Tāmaki Herenga Manawa | B12: Under 2's | C12: 5103.6083 | D12: 5700.6184 | E12: 6341.6405 | F12: 6887.7629 | G12: 8773.7163 | H12: 10272.312 | I12: 12867.582 | J12: 14234.25 | K12: 14878.928 | L12: 15284.463 | M12: 19646.628 | N12: 25011.873 | O12: 30555.726 | P12: 34643.607 | Q12: 38271.667 | R12: 38660.906 | S12: 40971.168 | T12: 43372.236 | U12: 43775.586 | V12: 48771.705 | W12: 51278.441 | X12: 58884.104
A13: Tāmaki Herenga Manawa | B13: 2 and over - non 20 Hours ECE | C13: 17398.168 | D13: 19133.055 | E13: 21115.35 | F13: 23960.51 | G13: 29271.598 | H13: 33640.109 | I13: 19958.4 | J13: 20900.862 | K13: 21861.177 | L13: 22130.632 | M13: 24496.97 | N13: 28001.876 | O13: 31884.443 | P13: 36007.045 | Q13: 39032.129 | R13: 42264.165 | S13: 43962.028 | T13: 47428.866 | U13: 49720.345 | V13: 51343.68 | W13: 54267.272 | X13: 59418.136
A14: Tāmaki Herenga Manawa | B14: Equity | C14: 140.0645 | D14: 282.86198 | E14: 282.88392 | F14: 301.82144 | G14: 324.83772 | H14: 339.7726 | I14: 335.36808 | J14: 407.60971 | K14: 406.41895 | L14: 417.20282 | M14: 494.03113 | N14: 830.20427 | O14: 1375.7754 | P14: 1765.1723 | Q14: 2171.5948 | R14: 2420.0716 | S14: 2518.5561 | T14: 2775.7445 | U14: 2907.4627 | V14: 3049.392 | W14: 3111.8593 | X14: 3182.6089
A15: Tāmaki Herenga Manawa | B15: Targeted Funding for Disadvantage | C15: 0 | D15: 0 | E15: 0 | F15: 0 | G15: 0 | H15: 0 | I15: 0 | J15: 0 | K15: 0 | L15: 0 | M15: 0 | N15: 0 | O15: 0 | P15: 0 | Q15: 0 | R15: 0 | S15: 185.94175 | T15: 360.45928 | U15: 342.01368 | V15: 351.50738 | W15: 371.17138 | X15: 410.79645
A16: Tāmaki Herenga Manawa | B16: Total | C16: 22641.84 | D16: 25116.535 | E16: 27739.875 | F16: 31150.095 | G16: 38370.152 | H16: 44252.194 | I16: 64647.621 | J16: 82011.711 | K16: 90404.296 | L16: 96284.587 | M16: 111527.75 | N16: 131107.44 | O16: 152481.74 | P16: 168980.85 | Q16: 180852.95 | R16: 187087.33 | S16: 193142.99 | T16: 201633.4 | U16: 208676.89 | V16: 222208.35 | W16: 226938.83 | X16: 243797.1
... A88: Total | B88: Total | C88: 302864.04 | D88: 344391.96 | E88: 373238.91 | F88: 411706.92 | G88: 496476.84 | H88: 564286.95 | I88: 817900.71 | J88: 1026788.4 | K88: 1169325 | L88: 1255904 | M88: 1305814.3 | N88: 1388788.3 | O88: 1508694.3 | P88: 1607689.9 | Q88: 1698932.7 | R88: 1753786.4 | S88: 1810524.3 | T88: 1869377.8 | U88: 1962027.7 | V88: 2096777.7 | W88: 2172070.9 | X88: 2316512.2

Sheet EXP9
A1: ='Table Index'!J13 -> Entitlement funding, equity funding and targeted funding for disadvantage by New Zealand Index of Deprivation and programme ($000, GST exclusive) | M1: About the data in this table | P1: Table Index
A3: Click on arrow to select (filter) the information you need
A4: NZDep18 Index of Deprivation 18 | B4: Programme 14 | C4: 2001/02 | D4: 2002/03 | E4: 2003/04 | F4: 2004/05 | G4: 2005/06 | H4: 2006/07 | I4: 2007/08 | J4: 2008/09 | K4: 2009/10 | L4: 2010/11 | M4: 2011/12 | N4: 2012/13 | O4: 2013/14 | P4: 2014/15 | Q4: 2015/16 | R4: 2016/17 | S4: 2017/18 | T4: 2018/19 | U4: 2019/20 | V4: 2020/21 | W4: 2021/22 | X4: 2022/23
A5: NZDep decile 1 | B5: 20 Hours ECE | C5: 0 | D5: 0 | E5: 0 | F5: 0 | G5: 0 | H5: 0 | I5: 18761.704 | J5: 26584.876 | K5: 32683.878 | L5: 38166.961 | M5: 38789.622 | N5: 41129.839 | O5: 45645.767 | P5: 48225.97 | Q5: 51468.637 | R5: 55135.602 | S5: 56705.638 | T5: 59772.299 | U5: 64464.106 | V5: 71558.573 | W5: 74354.684 | X5: 78440.423
A6: NZDep decile 1 | B6: Under 2's | C6: 3000.7421 | D6: 3132.322 | E6: 3835.3735 | F6: 4903.5031 | G6: 5574.9892 | H6: 6591.7593 | I6: 8107.2587 | J6: 9477.8933 | K6: 10625.175 | L6: 11417.365 | M6: 11213.522 | N6: 11213.801 | O6: 12656.948 | P6: 13218.72 | Q6: 14673.817 | R6: 17223.893 | S6: 18140.75 | T6: 18794.892 | U6: 20547.51 | V6: 23928.387 | W6: 26059.198 | X6: 30330.748
A7: NZDep decile 1 | B7: 2 and over - non 20 Hours ECE | C7: 8994.6492 | D7: 9984.5777 | E7: 11328.941 | F7: 12961.448 | G7: 16020.98 | H7: 18800.564 | I7: 10706.018 | J7: 11940.272 | K7: 12811.065 | L7: 12860.589 | M7: 11881.188 | N7: 12186.778 | O7: 13778.297 | P7: 15177.577 | Q7: 16457.689 | R7: 18346.444 | S7: 20169.157 | T7: 21729.729 | U7: 23165.874 | V7: 25790.287 | W7: 28401.172 | X7: 31204.331
A8: NZDep decile 1 | B8: Equity | C8: 13.783893 | D8: 29.157849 | E8: 31.52656 | F8: 31.424133 | G8: 32.51872 | H8: 28.93104 | I8: 32.663049 | J8: 47.70256 | K8: 36.828105 | L8: 40.002348 | M8: 60.048843 | N8: 98.53182 | O8: 235.7345 | P8: 258.25642 | Q8: 279.41782 | R8: 276.13491 | S8: 280.5319 | T8: 276.88006 | U8: 318.71569 | V8: 403.41065 | W8: 431.05107 | X8: 427.64095
A9: NZDep decile 1 | B9: Targeted Funding for Disadvantage | C9: 0 | D9: 0 | E9: 0 | F9: 0 | G9: 0 | H9: 0 | I9: 0 | J9: 0 | K9: 0 | L9: 0 | M9: 0 | N9: 0 | O9: 0 | P9: 0 | Q9: 0 | R9: 0 | S9: 43.385478 | T9: 78.071624 | U9: 68.138959 | V9: 72.85514 | W9: 66.552174 | X9: 48.99696
A10: NZDep decile 1 | B10: Total | C10: 12009.175 | D10: 13146.058 | E10: 15195.841 | F10: 17896.375 | G10: 21628.488 | H10: 25421.254 | I10: 37607.644 | J10: 48050.745 | K10: 56156.947 | L10: 62484.917 | M10: 61944.38 | N10: 64628.949 | O10: 72316.747 | P10: 76880.523 | Q10: 82879.561 | R10: 90982.073 | S10: 95339.462 | T10: 100651.87 | U10: 108564.34 | V10: 121753.51 | W10: 129312.66 | X10: 140452.14
A11: NZDep decile 2 | B11: 20 Hours ECE | C11: 0 | D11: 0 | E11: 0 | F11: 0 | G11: 0 | H11: 0 | I11: 17247.937 | J11: 26512.386 | K11: 31984.219 | L11: 34609.287 | M11: 36731.995 | N11: 38233.919 | O11: 41124.402 | P11: 43710.584 | Q11: 44679.593 | R11: 45150.718 | S11: 47369.516 | T11: 49193.636 | U11: 52337.49 | V11: 58219.148 | W11: 60650.082 | X11: 64726.029
A12: NZDep decile 2 | B12: Under 2's | C12: 5044.092 | D12: 4984.5048 | E12: 5512.9793 | F12: 5977.6907 | G12: 7369.515 | H12: 8592.2285 | I12: 9683.4182 | J12: 10532.208 | K12: 11571.965 | L12: 11823.886 | M12: 12213.153 | N12: 12579.002 | O12: 13903.819 | P12: 14031.159 | Q12: 15380.772 | R12: 15842.51 | S12: 17524.358 | T12: 18639.058 | U12: 18633.047 | V12: 20858.225 | W12: 22541.923 | X12: 26781.277
A13: NZDep decile 2 | B13: 2 and over - non 20 Hours ECE | C13: 9928.7318 | D13: 10877.826 | E13: 11653.525 | F13: 12876.694 | G13: 16068.656 | H13: 18830.448 | I13: 11665.851 | J13: 12242.875 | K13: 12281.022 | L13: 11953.72 | M13: 12127.518 | N13: 12866.168 | O13: 13655.937 | P13: 14578.998 | Q13: 15373.219 | R13: 16556.982 | S13: 17765.089 | T13: 18886.995 | U13: 19817.947 | V13: 20919.827 | W13: 23069.446 | X13: 25677.19
A14: NZDep decile 2 | B14: Equity | C14: 31.894107 | D14: 63.515067 | E14: 57.603253 | F14: 52.650933 | G14: 45.902507 | H14: 40.7212 | I14: 46.204311 | J14: 58.656689 | K14: 58.470878 | L14: 60.762285 | M14: 114.40749 | N14: 195.45933 | O14: 288.54452 | P14: 289.32262 | Q14: 354.44823 | R14: 341.198 | S14: 363.25134 | T14: 357.94283 | U14: 360.23755 | V14: 355.74303 | W14: 326.29015 | X14: 324.5426
A15: NZDep decile 2 | B15: Targeted Funding for Disadvantage | C15: 0 | D15: 0 | E15: 0 | F15: 0 | G15: 0 | H15: 0 | I15: 0 | J15: 0 | K15: 0 | L15: 0 | M15: 0 | N15: 0 | O15: 0 | P15: 0 | Q15: 0 | R15: 0 | S15: 66.659846 | T15: 120.32628 | U15: 99.30584 | V15: 114.697 | W15: 123.23739 | X15: 141.01126
A16: NZDep decile 2 | B16: Total | C16: 15004.718 | D16: 15925.845 | E16: 17224.107 | F16: 18907.035 | G16: 23484.074 | H16: 27463.398 | I16: 38643.411 | J16: 49346.125 | K16: 55895.677 | L16: 58447.655 | M16: 61187.073 | N16: 63874.548 | O16: 68972.703 | P16: 72610.064 | Q16: 75788.033 | R16: 77891.408 | S16: 83088.874 | T16: 87197.959 | U16: 91248.027 | V16: 100467.64 | W16: 106710.98 | X16: 117650.05
... A76: Total | B76: Total | C76: 302864.04 | D76: 344391.96 | E76: 373238.91 | F76: 411706.92 | G76: 496476.84 | H76: 564286.95 | I76: 817900.71 | J76: 1026788.4 | K76: 1169325 | L76: 1255904 | M76: 1305814.3 | N76: 1388788.3 | O76: 1508694.3 | P76: 1607689.9 | Q76: 1698932.7 | R76: 1753786.4 | S76: 1810524.3 | T76: 1869377.8 | U76: 1962027.7 | V76: 2096777.7 | W76: 2172070.9 | X76: 2316512.2

Sheet EXP10
A1: ='Table Index'!J14 -> Entitlement funding, equity funding and targeted funding for disadvantage per funded child hour by service type and programme ($, GST exclusive) | M1: About the data in this table | P1: Table Index
A2: Note that for this table, Education & Care services includes both Casual Education & Care and Hospital-based services. Kōhanga reo includes unlicensed Kōhanga reo up to 2008.
A4: Click on arrow to select (filter) the information you need
A5: Service type 13 | B5: Programme 14 | C5: 2001/02 | D5: 2002/03 | E5: 2003/04 | F5: 2004/05 | G5: 2005/06 | H5: 2006/07 | I5: 2007/08 | J5: 2008/09 | K5: 2009/10 | L5: 2010/11 | M5: 2011/12 | N5: 2012/13 | O5: 2013/14 | P5: 2014/15 | Q5: 2015/16 | R5: 2016/17 | S5: 2017/18 | T5: 2018/19 | U5: 2019/20 | V5: 2020/21 | W5: 2021/22 | X5: 2022/23
A6: Education & Care | B6: 20 Hours ECE | I6: 8.6090122 | J6: 9.5223692 | K6: 9.8612123 | L6: 9.7718978 | M6: 9.7022673 | N6: 9.7402819 | O6: 9.8237377 | P6: 9.9164887 | Q6: 9.9212882 | R6: 9.9209794 | S6: 9.921886 | T6: 9.9973205 | U6: 10.174373 | V6: 10.608682 | W6: 11.005206 | X6: 11.749516
A7: Education & Care | B7: Under 2's | C7: 5.153482 | D7: 5.2797169 | E7: 5.4800807 | F7: 5.8439762 | G7: 7.0566641 | H7: 7.859665 | I7: 8.6959502 | J7: 9.3450118 | K7: 10.168443 | L7: 10.176273 | M7: 10.23822 | N7: 10.305789 | O7: 10.401236 | P7: 10.502144 | Q7: 10.506286 | R7: 10.506643 | S7: 10.506363 | T7: 10.589117 | U7: 10.780151 | V7: 11.218507 | W7: 11.598372 | X7: 12.386566
A8: Education & Care | B8: 2 and over - non 20 Hours ECE | C8: 2.5762444 | D8: 2.6439955 | E8: 2.742875 | F8: 2.9488949 | G8: 3.6764487 | H8: 4.1446084 | I8: 4.4728399 | J8: 5.3775463 | K8: 5.6925357 | L8: 5.6539807 | M8: 5.6174017 | N8: 5.6707453 | O8: 5.7284061 | P8: 5.7891654 | Q8: 5.794153 | R8: 5.7947677 | S8: 5.7951527 | T8: 5.8404725 | U8: 5.9492583 | V8: 6.2112421 | W8: 6.4893991 | X8: 6.9284243
A9: Education & Care | B9: Equity | C9: 0.021046981 | D9: 0.041034953 | E9: 0.039934894 | F9: 0.039845042 | G9: 0.040724265 | H9: 0.042486272 | I9: 0.040118756 | J9: 0.042816593 | K9: 0.040858411 | L9: 0.040665509 | M9: 0.072295731 | N9: 0.12055321 | O9: 0.17608373 | P9: 0.1868137 | Q9: 0.1935846 | R9: 0.19839233 | S9: 0.20075867 | T9: 0.19716986 | U9: 0.20077237 | V9: 0.2011694 | W9: 0.2035383 | X9: 0.20369382
A10: Education & Care | B10: Targeted Funding for Disadvantage | C10: 0 | D10: 0 | E10: 0 | F10: 0 | G10: 0 | H10: 0 | I10: 0 | J10: 0 | K10: 0 | L10: 0 | M10: 0 | N10: 0 | O10: 0 | P10: 0 | Q10: 0 | R10: 0 | S10: 0.019187764 | T10: 0.036355603 | U10: 0.036148141 | V10: 0.037198404 | W10: 0.036880006 | X10: 0.036842575
A11: Education & Care | B11: Total | C11: 3.1389303 | D11: 3.222765 | E11: 3.3538629 | F11: 3.6076603 | G11: 4.4507213 | H11: 4.9832651 | I11: 6.6969196 | J11: 7.8942992 | K11: 8.414454 | L11: 8.4356366 | M11: 8.4788975 | N11: 8.589473 | O11: 8.7347631 | P11: 8.8192354 | Q11: 8.8290174 | R11: 8.7891523 | S11: 8.7942223 | T11: 8.8519507 | U11: 9.0076277 | V11: 9.4298174 | W11: 9.7650793 | X11: 10.414911
A12: Home-based | B12: 20 Hours ECE | I12: 7.3933418 | J12: 7.5789178 | K12: 7.6804467 | L12: 7.7042133 | M12: 7.7584315 | N12: 7.7470787 | O12: 7.7700747 | P12: 7.7976068 | Q12: 7.7681616 | R12: 7.7670932 | S12: 7.7650005 | T12: 7.7736265 | U12: 7.8467025 | V12: 8.0934063 | W12: 8.3897679 | X12: 8.6940259
A13: Home-based | B13: Under 2's | C13: 5.0976776 | D13: 5.1325266 | E13: 5.2410049 | F13: 5.4254808 | G13: 5.7082102 | H13: 6.0213098 | I13: 6.3742049 | J13: 6.503098 | K13: 6.537077 | L13: 6.5563335 | M13: 6.6001397 | N13: 6.5735105 | O13: 6.555125 | P13: 6.5586524 | Q13: 6.5394486 | R13: 6.5480301 | S13: 6.5477756 | T13: 6.5306069 | U13: 6.5833179 | V13: 6.7561209 | W13: 6.9958306 | X13: 7.3376752
A14: Home-based | B14: 2 and over - non 20 Hours ECE | C14: 2.552839 | D14: 2.5730945 | E14: 2.6259178 | F14: 2.736297 | G14: 2.9675659 | H14: 3.1748864 | I14: 3.3487688 | J14: 3.4714263 | K14: 3.5231136 | L14: 3.5368873 | M14: 3.5566307 | N14: 3.5506253 | O14: 3.5466632 | P14: 3.5515967 | Q14: 3.5380421 | R14: 3.5377232 | S14: 3.5343637 | T14: 3.5265009 | U14: 3.5532162 | V14: 3.6311215 | W14: 3.7605734 | X14: 3.932066
A15: Home-based | B15: Equity | C15: 0.0096664847 | D15: 0.015177301 | E15: 0.013632498 | F15: 0.010661901 | G15: 0.0097014166 | H15: 0.0088370627 | I15: 0.011409723 | J15: 0.014197354 | K15: 0.012137395 | L15: 0.010861553 | M15: 0.039880409 | N15: 0.086704719 | O15: 0.15899005 | P15: 0.18204505 | Q15: 0.20015918 | R15: 0.24164131 | S15: 0.28592213 | T15: 0.29856529 | U15: 0.32309085 | V15: 0.30782608 | W15: 0.30317713 | X15: 0.30257853
