Workbook

Sheet Guidance for agencies
A1: Secretary and Chief Executive Expense Disclosures: A Guide for Agency Staff
A2: The following is a summary from "Public Service Secretaries and Chief Executive Expense Disclosures: A Guide for Agency Staff" Please read that in full first.
A4: In the following worksheets, cells shaded light green require input. All other cells are locked to prevent change.
A6: Purpose
A7: The purpose of regular public disclosure of secretaries and/or chief executive's expenses is to provide transparency and accountability for discretionary expenditure by Public Service agencies and statutory Crown entities.
A8: Publishing clear and detailed disclosures is integral to building and maintaining the public's trust and confidence in the Public service.
A10: What is covered? | B10: Description (e.g. event tickets, etc)
A11: All expenses for items offered, accepted or declined by secretaries or chief executives in performing their role are required to be disclosed, whether paid by credit card or invoiced.
A12: This includes expenses for more personal undertakings, such as professional development expenditure, in addition to outgoings for the likes of travel and entertainment.
A13: Secretary and chief executive expenses are not generally regarded as personal or commercially sensitive. Refer to the Ombudsman Guide to Chief Executive Expenses for guidance.
A14: Business or corporate expenses for the organisation that are met from the secretaries or chief executive's budget or paid by their credit card are excluded.
A15: Expense disclosures cover the full period of the report, and are completed by each secretary or chief executive, including in Acting roles - Complete a separate workbook for each.
A17: How does it work?
A18: Secretaries or chief executives disclose the expenses, gifts & hospitality they have expended or been offered using this Excel workbook.
A19: Secretaries or chief executives formally approve completed Excel workbooks and an appropriate person reviews them (see guidance).
A20: They are posted on agency websites and linked to www.data.govt.nz. See: https://www.data.govt.nz/toolkit/how-do-i-add-or-update-our-chief-executive-expenses/
A22: When and how often are disclosures made?
A23: Disclosures cover the year to 30 June and are expected to be published by 31 July.
A25: Disclosed Information - this workbook includes a tab for each of the following categories:
... A58: Provide information using the Commissions Excel workbook - Click Here

Sheet Summary and sign-off
A1: Secretary or Chief Executive Expenses, Gifts and Benefits Disclosure - summary & sign-off*
A2: Organisation Name* | B2: Sport NZ
A3: Secretary or Chief Executive** | B3: Raelene Castle
A4: Disclosure period start*** | B4: 45474
A5: Disclosure period end*** | B5: 45838
A6: Agency totals check | B6: =IF(AND(Travel!B7<>A30,Hospitality!B7<>A30,'All other expenses'!B7<>A30,'Gifts and benefits'!B7<>A30),A31,IF(AND(Travel!B7=A30,Hospitality!B7=A30,'All other expenses'!B7=A30,'Gifts and benefits'!B7=A30),A33,A32)) -> Data and totals checked on all sheets
A7: Secretary or Chief Executive approval**** | B7: This disclosure has been approved by the Departmental Secretary or Chief Executive
A8: Other sign-off**** | B8: GM Corporate Services
A9: This summary page updates automatically from the 'Travel', 'Hospitality', 'All other expenses', and 'Gifts and benefits' tabs. Throughout this workbook, input cells are shaded light green.
A10: Summary of expenses | B10: Cost in NZ$ | C10: GST inc / exc | E10: Gifts and benefits | F10: Count
A11: Travel expenses | B11: =B15+B16+B17 -> 94812.52 | C11: =IF(Travel!B6="",A34,Travel!B6) -> Figures exclude GST | E11: Number offered | F11: ='Gifts and benefits'!C27 -> 13
A12: Hospitality | B12: =Hospitality!B21 -> 702.76 | C12: =IF(Hospitality!B6="",A34,Hospitality!B6) -> Figures exclude GST | E12: Number accepted | F12: ='Gifts and benefits'!C28 -> 12
A13: Other expenses | B13: ='All other expenses'!B25 -> 0 | C13: =IF('All other expenses'!B6="",A34,'All other expenses'!B6) -> Figures exclude GST | E13: Number declined | F13: ='Gifts and benefits'!C29 -> 1
A15: International Travel | B15: =Travel!B31 -> 50602.88 | C15: =C11 -> Figures exclude GST
A16: Domestic Travel | B16: =Travel!B245 -> 43910.19 | C16: =C11 -> Figures exclude GST
A17: Local Travel | B17: =Travel!B264 -> 299.45 | C17: =C11 -> Figures exclude GST
A19: Notes
A20: * Headings on following tabs will pre populate with what you enter on this tab
A21: ** Create a new workbook for a new or Acting Departmental secretary or Chief Executive
A22: *** Update if a shorter or different period is covered
A23: **** This disclosure must be approved by the Departmental secretary or Chief Executive and another appropriate party, e.g. Board Chair, Chief Financial Officer or Audit and Risk Committee member
A25: Text required for validation and checks - don't change, move, delete or overwrite
A26: Insert additional rows as needed: right click on a row number (left of screen) and select Insert - this will insert a row above selected row.
A27: Figures include GST (where applicable)
A28: Figures exclude GST
A29: Data and totals on this worksheet have NOT YET BEEN CHECKED AND CONFIRMED
A30: Data and totals on this worksheet checked and confirmed
A31: Data and totals have not yet been checked and confirmed for any sheet
... A46: Declined
A47: -20000
A48: Check - there are no hidden rows with data
A49: Error - this total includes data from 'hidden' rows
A50: Check - each entry provides sufficient information
A51: Not all lines have an entry for "Cost in NZ$" and "Type of expense"
A52: Not all lines have an entry for "Description", "Was the gift accepted?" and "Estimated value in NZ$"
A53: Check that # of 'costs' = 'type of expenses' (also "accepted/declined" for gifts & benefits) | F53: TRUE
A54: These checks (F53 to F61) are imperfect - they count the entries in each column and checks these totals are the same | F54: FALSE
B55: =COUNT(Travel!B12:B30) -> 14 | D55: =COUNTIF(Travel!D12:D30,"*") -> 14 | F55: =MIN(B55,D55)=MAX(B55,D55) -> TRUE
A56: Travel checks | B56: =COUNT(Travel!B35:B244) -> 154 | D56: =COUNTIF(Travel!D35:D244,"*") -> 140 | F56: =MIN(B56,D56)=MAX(B56,D56) -> FALSE
B57: =COUNT(Travel!B249:B263) -> 12 | D57: =COUNTIF(Travel!D249:D263,"*") -> 12 | F57: =MIN(B57,D57)=MAX(B57,D57) -> TRUE
...

Sheet Travel
A1: Public Service Secretary or Chief Executive Expense Disclosure
A2: Organisation Name | B2: ='Summary and sign-off'!B2:F2 -> Sport NZ
A3: Public Service Secretary or Chief Executive | B3: ='Summary and sign-off'!B3:F3 -> Raelene Castle
A4: Disclosure period start | B4: ='Summary and sign-off'!B4:F4 -> 45474
A5: Disclosure period end | B5: ='Summary and sign-off'!B5:F5 -> 45838
A6: GST on costs | B6: Figures exclude GST
A7: Agency totals check | B7: Data and totals on this worksheet checked and confirmed
A8: International, domestic and local travel expenses
A9: All expenses incurred by Public Service secretary or chief executive during international, domestic and local travel. Group expenses relating to each trip.
A10: International Travel (including travel within NZ at beginning and end of overseas trip)
A11: Date(s)* | B11: Cost in NZ$** | C11: Purpose of travel (e.g. attending XYZ conference for 3 days)*** | D11: Type of expense (e.g. hotel, airfares, taxis, meals & for how many people) | E11: Location(s)
A12: 19 July - 19 Aug 2024 | B12: 11453 | C12: Meeting with Int Network of Sports Councils (Lon); Paris Olympics and associated international meetings | D12: Airfares | E12: Akld/LHR/Paris/Akld
A13: 19 July - 19 Aug 2024 | B13: 4127.2727 | C13: Travel within Paris to Olympic events and associated international meetings | D13: Event tickets | E13: Paris
A14: 19 July - 19 Aug 2024 | B14: 1159 | C14: Meeting with Int Network of Sports Councils (Lon); Paris Olympics and associated international meetings | D14: Trains x2 inc changes | E14: Lon/Paris one way and Paris/Marseille rtn
A15: 19 July - 19 Aug 2024 | B15: 3928.5068 | C15: Travel within Paris to Olympic events and associated international meetings | D15: Transport between olympic events x6 | E15: Paris
A16: 19 July - 19 Aug 2024 | B16: =(61.81+53.04+40.87+37.5+37.11+20.11+31.83+28.64+27.72+26.97+28.13+29+26.21+60.47+22.32+35.6+46.32+43.19+26.68+27.35+37.03+24.2+26.13+23.54+20.03+20.07+37.31+30.4+48.37+112.66+110) -> 1200.61 | C16: Meeting with Int Network of Sports Councils (Lon); Paris Olympics and associated international meetings | D16: Ubers x 31 | E16: London and Paris
A17: 19-22 July 2024 | B17: =+(210+182+64) -> 456 | C17: Getting to meetings, train stations in London | D17: Taxis x 3 | E17: London
A18: 21 July - 22 July 2024 | B18: 985.5 | C18: Meeting with International Network of Sports Councils (Lon) | D18: Accommodation x2 nights | E18: London
A19: 19 July - 19 Aug 2024 | B19: 18498.98 | C19: Paris Olympics and associated international meetings | D19: Accommodation x23 nights | E19: Paris / Marseille
A22: 11-17 June 2025 | B22: 6181 | C22: Meeting with Sport Singapore; Sport England & UK Sport; Arup, Laureus Sport | D22: Airfare (Premium Eco) | E22: Akld/Sing/Lon rtn
A23: 11 & 12 June 2025 | B23: 694 | C23: Meetings with Sport Singapore | D23: Accommodation x 2 nights | E23: Singapore
A24: 11 & 12 June 2025 | B24: 136.24 | C24: Meetings with Sport Singapore | D24: Taxis | E24: Singapore
A25: 16 & 17 June 2025 | B25: 800 | C25: Meetings with Sport England, UK Sport,Arup, Laureus Sport for Good | D25: Accommodation x 2 nights | E25: London
A26: 16 & 17 June 2025 | B26: =(133.85+80.22+86.6+86.6+74.49+59.57+108.03+50.79+250.46) -> 930.61 | C26: Meetings with Sport England, UK Sport, Arup, Laureus Sport for Good | D26: Ubers/taxis | E26: London
A27: 45844 | B27: 52.16 | C27: Returning to NZ from above meetings in England | D27: Uber | E27: Auckland
A31: Subtotal - international travel | B31: =SUM(B12:B30) -> 50602.88 | C31: =IF(SUBTOTAL(3,B12:B30)=SUBTOTAL(103,B12:B30),'Summary and sign-off'!$A$48,'Summary and sign-off'!$A$49) -> Check - there are no hidden rows with data | D31: =IF('Summary and sign-off'!F55='Summary and sign-off'!F54,'Summary and sign-off'!A51,'Summary and sign-off'!A50) -> Check - each entry provides sufficient information
A33: Domestic Travel (within NZ, including travel to and from local airport)
A34: Date(s)* | B34: Cost in NZ$ | C34: Purpose of travel (e.g. visiting district office for two days...)*** | D34: Type of expense (e.g. hotel, airfares, taxis, meals & for how many people) | E34: Location(s)
A35: 1-3 July 2024 | B35: 614.89 | C35: Meetings with Chch staff, local partners in Chch, tour of Parakiore; mtgs in Wellington | D35: airfare | E35: Akld/Chch/Wgtn/Akld
A36: 1-3 July 2024 | B36: 130.53 | C36: Meetings with Chch staff, local partners in Chch, tour of Parakiore; mtgs in Wellington | D36: Ubers x5 | E36: Akld/Chch/Wgtn
A37: 1-3 July 2024 | B37: 195.65 | C37: Meetings with Chch staff, local partners in Chch, tour of Parakiore; mtgs in Wellington | D37: Accommodation | E37: Christchurch
A38: 1-3 July 2024 | B38: 226.09 | C38: Meetings with Chch staff, local partners in Chch, tour of Parakiore; mtgs in Wellington | D38: Accommodation | E38: Wellington
A40: 8/9 July 2024 | B40: 361.02 | C40: Meetings in Wgtn | D40: Airfare | E40: Akld/Wgtn rtn
A41: 8/9 July 2024 | B41: 226.09 | C41: Meetings in Wgtn | D41: Accommodation | E41: Wellington
A42: 8/9 July 2024 | B42: 130.28 | C42: Meetings in Wgtn | D42: Ubers x3 | E42: Akld & Wgtn
A44: 45504 | B44: 30.99 | C44: Travel services costs for July
A46: 21-23 Aug 2024 | B46: 361.02 | C46: Sport NZ Board meeting; meetings with staff; speaking NZ Universities l/ship prog | D46: Airfare | E46: Akld/Wgtn rtn
A47: 21-23 Aug 2024 | B47: 203.11 | C47: Sport NZ Board meeting; meetings with staff; speaking NZ Universities l/ship prog | D47: Ubers x5 | E47: Akld & Wgtn
A48: 21-23 Aug 2024 | B48: 452.17 | C48: Sport NZ Board meeting; meetings with staff; speaking NZ Universities l/ship prog | D48: accommodation x 2 nights | E48: Wgtn
A50: 27-29 Aug 2024 | B50: 337.4 | C50: RST hui, local govt hui, meetings with staff | D50: Airfare | E50: Akld/Wgtn rtn
...

Sheet Hospitality
A1: Public Service Secretary or Chief Executive Expense Disclosure
A2: Organisation Name | B2: ='Summary and sign-off'!B2:F2 -> Sport NZ
A3: Public Service Secretary or Chief Executive | B3: ='Summary and sign-off'!B3:F3 -> Raelene Castle
A4: Disclosure period start | B4: ='Summary and sign-off'!B4:F4 -> 45474
A5: Disclosure period end | B5: ='Summary and sign-off'!B5:F5 -> 45838
A6: GST on costs | B6: Figures exclude GST
A7: Agency totals check | B7: Data and totals on this worksheet checked and confirmed
A8: Hospitality Offered to Third Parties*
A9: All hospitality expenses provided by the Public Service secretary or chief executive in the context of their job to anyone external to the Public Service or statutory Crown entities.
A10: Date(s)** | B10: Cost in NZ$ | C10: Purpose of hospitality (e.g. hosting delegation from China, building relationships, team building) | D10: Type of expense (what and for how many e.g. dinner for 5) | E10: Location(s)
A11: 45475 | B11: 33.04 | C11: Meeting with Sport Canterbury | D11: Breakfast, 2 pax | E11: Christchurch | F11: ex GST
A12: 45489 | B12: 57.01 | C12: Meeting with Netball NZ | D12: Breakfast, 2 pax | E12: Auckland | F12: ex GST
A13: 45576 | B13: 52.07 | C13: Meeting with new Rowing NZ CEO | D13: Breakfast, 2 pax | E13: Auckland | F13: ex GST
A14: 45723 | B14: 52.07 | C14: Meeting with Waterpolo NZ | D14: Breakfast, 2 pax | E14: Auckland | F14: ex GST
A15: 45758 | B15: 32.37 | C15: Meeting with NZRL | D15: Breakfast, 2 pax | E15: Auckland | F15: ex GST
A16: 45782 | B16: 397.07 | C16: Meeting with International Representatives Network for Sport | D16: Dinner, 18 pax | E16: Auckland | F16: ex GST
A17: 45785 | B17: 41.74 | C17: Meeting with Basketball NZ | D17: Lunch, 2 pax | E17: Auckland | F17: ex GST
A18: 45814 | B18: 37.39 | C18: Meeting with Athletics NZ | D18: Breakfast, 2 pax | E18: Auckland | F18: ex GST
A21: Total hospitality expenses | B21: =SUM(B11:B20) -> 702.76 | C21: =IF(SUBTOTAL(3,B11:B20)=SUBTOTAL(103,B11:B20),'Summary and sign-off'!$A$48,'Summary and sign-off'!$A$49) -> Check - there are no hidden rows with data | D21: =IF('Summary and sign-off'!F58='Summary and sign-off'!F54,'Summary and sign-off'!A51,'Summary and sign-off'!A50) -> Check - each entry provides sufficient information
A23: Notes
A24: * Third parties include people and organisations external to the public service or statutory Crown entities.
A25: ** Any non-standard date format or date outside 1 July - 30 June will raise an alert. Check entry and select 'Yes' to accept/continue.
A26: Insert additional rows as needed: right click on a row number (left of screen) and select Insert - this will insert a row above selected row.
A27: Total cost will appear automatically once you put information in rows above.
A28: Mark clearly if there is no information to disclose - provide a note to this effect in the 'Date' column (column A).

Sheet All other expenses
A1: Public Service Secretary or Chief Executive Expense Disclosure
A2: Organisation Name | B2: ='Summary and sign-off'!B2:F2 -> Sport NZ
A3: Public Service secretary or Chief Executive | B3: ='Summary and sign-off'!B3:F3 -> Raelene Castle
A4: Disclosure period start | B4: ='Summary and sign-off'!B4:F4 -> 45474
A5: Disclosure period end | B5: ='Summary and sign-off'!B5:F5 -> 45838
A6: GST on costs | B6: Figures exclude GST
A7: Agency totals check | B7: Data and totals on this worksheet checked and confirmed
A8: All Other Expenses
A9: All other expenditure incurred by the Public Service secretary or chief executive that is not travel, hospitality or gifts. Include e.g. phone and data costs, subscriptions, membership fees, conference fees, professional development costs, books and anything else.
A10: Date(s)* | B10: Cost in NZ$ | C10: Purpose of expense (e.g. subscription part of employment agreement, development as agreed with PSC) | D10: Type of expense (e.g. phone and data costs, membership fees) | E10: Location(s)
A25: Total other expenses | B25: =SUM(B11:B24) -> 0 | C25: =IF(SUBTOTAL(3,B11:B24)=SUBTOTAL(103,B11:B24),'Summary and sign-off'!$A$48,'Summary and sign-off'!$A$49) -> Check - there are no hidden rows with data | D25: =IF('Summary and sign-off'!F59='Summary and sign-off'!F54,'Summary and sign-off'!A51,'Summary and sign-off'!A50) -> Check - each entry provides sufficient information
A27: Notes
A28: * Any non-standard date format or date outside 1 July - 30 June will raise an alert. Check entry and select 'Yes' to accept/continue.
A29: Insert additional rows as needed: right click on a row number (left of screen) and select Insert - this will insert a row above selected row.
A30: Total cost will appear automatically once you put information in rows above.
A31: Mark clearly if there is no information to disclose - provide a note to this effect in the 'Date' column (column A).

Sheet Gifts and benefits
A1: Public Service Secretary or Chief Executive Gifts and Benefits Disclosure
A2: Organisation Name | B2: ='Summary and sign-off'!B2:F2 -> Sport NZ
A3: Public Service Secretary or Chief Executive | B3: ='Summary and sign-off'!B3:F3 -> Raelene Castle
A4: Disclosure period start | B4: ='Summary and sign-off'!B4:F4 -> 45474
A5: Disclosure period end | B5: ='Summary and sign-off'!B5:F5 -> 45838
A6: GST on values | B6: Figures exclude GST
A7: Agency totals check | B7: Data and totals on this worksheet checked and confirmed
A8: Gifts and Benefits over $50 annual value
A9: Include all gifts, invitations to events and other hospitality, of $50 or more in total value per year, offered to the Public Service secretary or chief executive by people external to the Public Service. Include all gifts, invitations or other hospitality whether accepted or declined.
A10: Date(s)* | B10: Description (e.g. event tickets, etc.) | C10: Was the gift accepted? (drop-down list in cell) | D10: Offered by (who made the offer?) | E10: Estimated value in NZ$ (drop-down list in cell but provide specific value if possible) | F10: Other comments (e.g. if given to others, whom?)
A11: 45486 | B11: Ticket and hosting All Blacks v England, Eden Park | C11: Accepted | D11: NZ Rugby | E11: $100 - $500
A12: 45564 | B12: Ticket Silver Ferns v England, Auckland | C12: Accepted | D12: Netball NZ | E12: Under $100
A13: 45567 | B13: Ticket and hosting Silver Ferns v England Roses, Wgtn | C13: Declined | D13: Netball NZ | E13: Under $100
A14: 45571 | B14: Ticket and hosting Silver Ferns v England Roses, Inv | C14: Accepted | D14: Netball NZ | E14: Under $100
A15: 45579 | B15: Ticket All Whites v Malaysia (friendly) | C15: Accepted | D15: NZ Football | E15: Under $100
A16: 45584 | B16: Ticket and hosting at Auckland FC v Brisbane Roar | C16: Accepted | D16: Auckland FC | E16: Under $100
A17: 45588 | B17: Ticket and hosting, Sliver Ferns v Australia, Auckland | C17: Accepted | D17: Netball NZ | E17: Under $100
A18: 45711 | B18: Ticket and hosting, Tall Blacks v Phillipines | C18: Accepted | D18: Basketball NZ | E18: Under $100
A19: 45720 | B19: Guest speaker, Wellington Women's Refuge dinner | C19: Accepted | D19: Wgtn Women's Refuge | E19: $100 - $500
A20: 45742 | B20: Ticket and hosting, T20 Women & Men | C20: Accepted | D20: NZ Cricket | E20: Under $100
A21: 45759 | B21: Ticket and hosting, Blues Double Header Eden Park | C21: Accepted | D21: Blues Ltd | E21: Under $100
A22: 45774 | B22: Ticket and hosting, Akld FC v Perth Glory | C22: Accepted | D22: Auckland FC | E22: Under $100
A23: 45794 | B23: Ticket and hosting, Black Ferns v Canada | C23: Accepted | D23: NZ Rugby | E23: Under $100
A27: Total count of gift/benefit entries: | B27: Offered | C27: =C28+C29 -> 13 | D27: =IF(SUBTOTAL(3,C11:C26)=SUBTOTAL(103,C11:C26),'Summary and sign-off'!$A$48,'Summary and sign-off'!$A$49) -> Check - there are no hidden rows with data | E27: =IF('Summary and sign-off'!F60='Summary and sign-off'!F54,'Summary and sign-off'!A52,'Summary and sign-off'!A50) -> Check - each entry provides sufficient information
B28: Accepted | C28: =COUNTIF(C11:C26,'Summary and sign-off'!A45) -> 12
B29: Declined | C29: =COUNTIF(C11:C26,'Summary and sign-off'!A46) -> 1
A31: Notes
A32: * Any non-standard date format or date outside 1 July - 30 June will raise an alert. Check entry and select 'Yes' to accept/continue.
A33: Insert additional rows as needed: right click on a row number (left of screen) and select Insert - this will insert a row above selected row.
A34: A one-off offer of something worth $25 is not included, but if the offer is made more than once a year, it should be disclosed.
A35: Include items such as invitations to functions and events, event tickets, gifts from overseas counterparts and commercial organisations (including that accepted by immediate family members).
A36: Include gifts and benefits that are declined.
A37: Number of gifts/benefits will update automatically once you put information in rows above.
A38: Mark clearly if there is no information to disclose - provide a note to this effect in the 'Date' column (column A).

Sheet Sheet1
